Workbook

Sheet Companies
A1: company_id | B1: company_name | C1: company_name_ar | D1: company_name_en | E1: normalized_name | F1: cr_number | G1: legal_type | H1: company_status | I1: registration_date | J1: industry | K1: activities | L1: governorate | M1: wilayat | N1: area | O1: address | P1: website | Q1: business_email | R1: business_phone | S1: vat_number | T1: tax_verification_status | U1: registered_supplier | V1: supplier_category | W1: supplier_classification | X1: tenders_participated | Y1: award_count | Z1: known_government_buyers | AA1: latest_award_date | AB1: latest_tender_activity | AC1: verification_status | AD1: confidence | AE1: last_verified_at | AF1: notes
A2: OMBI-0001 | B2: DHOFAR POULTRY CO. (S.A.O.G.) | C2: شركة ظفار للدواجن ش.م.ع.ع | D2: DHOFAR POULTRY CO. (S.A.O.G.) | E2: Dhofar Poultry Co. (S.A.O.G.) | G2: SAOG | J2: Food & Beverage | L2: Dhofar | T2: unknown | AC2: reported | AD2: 0.55 | AE2: 2026-09-21 | AF2: Public directory observation; CR, legal status, contact, tax and procurement fields not independently verified in this research pass.
A3: OMBI-0002 | B3: DHOFAR UNIVERSITY | C3: جامعة ظفار | D3: DHOFAR UNIVERSITY | E3: Dhofar University | J3: Education | L3: Dhofar | T3: unknown | AC3: reported | AD3: 0.55 | AE3: 2026-09-21 | AF3: Public directory observation; CR, legal status, contact, tax and procurement fields not independently verified in this research pass.
A4: OMBI-0003 | B4: DIAMOND GULF INTERNATIONAL L L C | C4: ماسة الخليج الدولية ش م م | D4: DIAMOND GULF INTERNATIONAL L L C | E4: Diamond Gulf International L L C | G4: LLC | J4: Other | L4: Muscat | T4: unknown | AC4: reported | AD4: 0.55 | AE4: 2026-09-21 | AF4: Public directory observation; CR, legal status, contact, tax and procurement fields not independently verified in this research pass.
A5: OMBI-0004 | B5: DIRECT SERVICES LLC | C5: شركة الخدمات المباشرة ش م م | D5: DIRECT SERVICES LLC | E5: Direct Services | G5: LLC | J5: Other | L5: Muscat | T5: unknown | AC5: reported | AD5: 0.55 | AE5: 2026-09-21 | AF5: Public directory observation; CR, legal status, contact, tax and procurement fields not independently verified in this research pass.
A6: OMBI-0005 | B6: DOHAT AL KHALEEJ L.L.C. | C6: دوحة الخليج ش . م . م | D6: DOHAT AL KHALEEJ L.L.C. | E6: Dohat Al Khaleej | G6: LLC | J6: Other | L6: Muscat | T6: unknown | AC6: reported | AD6: 0.55 | AE6: 2026-09-21 | AF6: Public directory observation; CR, legal status, contact, tax and procurement fields not independently verified in this research pass.
A7: OMBI-0006 | B7: DOHT AL SHMOOKH TRAD | C7: دوحه الشموخ للتجاره | D7: DOHT AL SHMOOKH TRAD | E7: Doht Al Shmookh Trad | J7: Trading | L7: Muscat | T7: unknown | AC7: reported | AD7: 0.55 | AE7: 2026-09-21 | AF7: Public directory observation; CR, legal status, contact, tax and procurement fields not independently verified in this research pass.
A8: OMBI-0007 | B8: DOKA MUSCAT SPC | C8: دوكا مسقط ش ش و | D8: DOKA MUSCAT SPC | E8: Doka Muscat | G8: SPC | J8: Other | L8: Muscat | T8: unknown | AC8: reported | AD8: 0.55 | AE8: 2026-09-21 | AF8: Public directory observation; CR, legal status, contact, tax and procurement fields not independently verified in this research pass.
A9: OMBI-0008 | B9: DOMINON VENTURES L L C | C9: المملكة للمشاريع ش م م | D9: DOMINON VENTURES L L C | E9: Dominon Ventures L L C | G9: LLC | J9: Construction | L9: Muscat | T9: unknown | AC9: reported | AD9: 0.55 | AE9: 2026-09-21 | AF9: Public directory observation; CR, legal status, contact, tax and procurement fields not independently verified in this research pass.
A10: OMBI-0009 | B10: DOUGLAS OHI LLC. | C10: دوجـــــلاس او اتش أي ش.م.م | D10: DOUGLAS OHI LLC. | E10: Douglas Ohi | G10: LLC | J10: Other | L10: Muscat | T10: unknown | AC10: reported | AD10: 0.55 | AE10: 2026-09-21 | AF10: Public directory observation; CR, legal status, contact, tax and procurement fields not independently verified in this research pass.
A11: OMBI-0010 | B11: DRAIEH CATERING & SERVICES CO. LLC | C11: شركة دراية للخدمات والتموين شِ.م.م | D11: DRAIEH CATERING & SERVICES CO. LLC | E11: Draieh Catering & Services Co | G11: LLC | J11: Food & Beverage | L11: Muscat | T11: unknown | AC11: reported | AD11: 0.55 | AE11: 2026-09-21 | AF11: Public directory observation; CR, legal status, contact, tax and procurement fields not independently verified in this research pass.
A12: OMBI-0011 | B12: DSV AIR AND SEA L L C | C12: دي اس في اير اند سي ش م م | D12: DSV AIR AND SEA L L C | E12: Dsv Air And Sea L L C | G12: LLC | J12: Logistics & Shipping | L12: Muscat | T12: unknown | AC12: reported | AD12: 0.55 | AE12: 2026-09-21 | AF12: Public directory observation; CR, legal status, contact, tax and procurement fields not independently verified in this research pass.
A13: OMBI-0012 | B13: DUCAB MUSCAT L.L.C | C13: دوكاب مسقط ش.م.م | D13: DUCAB MUSCAT L.L.C | E13: Ducab Muscat | G13: LLC | J13: Other | L13: Muscat | T13: unknown | AC13: reported | AD13: 0.55 | AE13: 2026-09-21 | AF13: Public directory observation; CR, legal status, contact, tax and procurement fields not independently verified in this research pass.
A14: OMBI-0013 | B14: DUQM POWER COMPANY LLC | C14: الدقم لتوليد الكهرباء ش م م | D14: DUQM POWER COMPANY LLC | E14: Duqm Power Company | G14: LLC | J14: Utilities | L14: Al Wusta | T14: unknown | AC14: reported | AD14: 0.55 | AE14: 2026-09-21 | AF14: Public directory observation; CR, legal status, contact, tax and procurement fields not independently verified in this research pass.
A15: OMBI-0014 | B15: DUQM REFINERY AND PATROCHEMICAL INDUSTRIES COMPANY L.L.C. | C15: شركة مصفاة الدقم والصناعات البتروكيماوية ش.م.م | D15: DUQM REFINERY AND PATROCHEMICAL INDUSTRIES COMPANY L.L.C. | E15: Duqm Refinery And Patrochemical Industries Company | G15: LLC | J15: Oil & Gas | L15: Al Wusta | T15: unknown | AC15: reported | AD15: 0.55 | AE15: 2026-09-21 | AF15: Public directory observation; CR, legal status, contact, tax and procurement fields not independently verified in this research pass.
A16: OMBI-0015 | B16: EAGLE HILLS MUSCAT PROPERTIES | C16: تلال النسور مسقط العقارية | D16: EAGLE HILLS MUSCAT PROPERTIES | E16: Eagle Hills Muscat Properties | J16: Real Estate | L16: Muscat | T16: unknown | AC16: reported | AD16: 0.55 | AE16: 2026-09-21 | AF16: Public directory observation; CR, legal status, contact, tax and procurement fields not independently verified in this research pass.
A17: OMBI-0016 | B17: ELECTRICITY HOLDING CO SAOC | C17: شركة الكهرباء القابضة ش.م.ع.م | D17: ELECTRICITY HOLDING CO SAOC | E17: Electricity Holding Co | G17: SAOC | J17: Utilities | L17: Muscat | T17: unknown | AC17: reported | AD17: 0.55 | AE17: 2026-09-21 | AF17: Public directory observation; CR, legal status, contact, tax and procurement fields not independently verified in this research pass.
A18: OMBI-0017 | B18: EMDAAD PETROLEUM SERVICES L.L.C | C18: شركة امداد للخدمات البترولية ش.م.م | D18: EMDAAD PETROLEUM SERVICES L.L.C | E18: Emdaad Petroleum Services | G18: LLC | J18: Oil & Gas | L18: Muscat | T18: unknown | AC18: reported | AD18: 0.55 | AE18: 2026-09-21 | AF18: Public directory observation; CR, legal status, contact, tax and procurement fields not independently verified in this research pass.
A19: OMBI-0018 | B19: EMDAD LOGISTICS SAOC | C19: شركة إمداد اللوجستية ش م ع م | D19: EMDAD LOGISTICS SAOC | E19: Emdad Logistics | G19: SAOC | J19: Logistics & Shipping | L19: Muscat | T19: unknown | AC19: reported | AD19: 0.55 | AE19: 2026-09-21 | AF19: Public directory observation; CR, legal status, contact, tax and procurement fields not independently verified in this research pass.
A20: OMBI-0019 | B20: ENOVA FACILITIES AND ENERGY MANAGEMENT SERVICES SPC | C20: إنوفا لخدمات إدارة المنشآت والطاقة ش ش و | D20: ENOVA FACILITIES AND ENERGY MANAGEMENT SERVICES SPC | E20: Enova Facilities And Energy Management Services | G20: SPC | J20: Utilities | L20: Dhofar | T20: unknown | AC20: reported | AD20: 0.55 | AE20: 2026-09-21 | AF20: Public directory observation; CR, legal status, contact, tax and procurement fields not independently verified in this research pass.
A21: OMBI-0020 | B21: ENROIL OILFIELD SOLUTIONS AND SERVICES | C21: انراويل لحلول وخدمات حقول النفط | D21: ENROIL OILFIELD SOLUTIONS AND SERVICES | E21: Enroil Oilfield Solutions And Services | J21: Oil & Gas | L21: Muscat | T21: unknown | AC21: reported | AD21: 0.55 | AE21: 2026-09-21 | AF21: Public directory observation; CR, legal status, contact, tax and procurement fields not independently verified in this research pass.
A22: OMBI-0021 | B22: ERNST & YOUNG L.L.C | C22: ارنست ويونغ ش.م.م | D22: ERNST & YOUNG L.L.C | E22: Ernst & Young | G22: LLC | J22: Other | L22: Muscat | T22: unknown | AC22: reported | AD22: 0.55 | AE22: 2026-09-21 | AF22: Public directory observation; CR, legal status, contact, tax and procurement fields not independently verified in this research pass.
A23: OMBI-0022 | B23: EXCEL TECHNICAL & INDUSTRIAL SUPPLIES L.L.C. | C23: المتميز للتجهيزات الصناعية الفنية ش.م.م | D23: EXCEL TECHNICAL & INDUSTRIAL SUPPLIES L.L.C. | E23: Excel Technical & Industrial Supplies | G23: LLC | J23: Manufacturing | L23: Muscat | T23: unknown | AC23: reported | AD23: 0.55 | AE23: 2026-09-21 | AF23: Public directory observation; CR, legal status, contact, tax and procurement fields not independently verified in this research pass.
A24: OMBI-0023 | B24: F&M MIDDLE EAST ENG. CONSULTACY L L C | C24: اف اند ام الشرق الاوسط للاستثارات الهندسية ش م م | D24: F&M MIDDLE EAST ENG. CONSULTACY L L C | E24: F&M Middle East Eng. Consultacy L L C | G24: LLC | J24: Construction | L24: Muscat | T24: unknown | AC24: reported | AD24: 0.55 | AE24: 2026-09-21 | AF24: Public directory observation; CR, legal status, contact, tax and procurement fields not independently verified in this research pass.
A25: OMBI-0024 | B25: FAHUD DESERT TRADING CO | C25: شركة صحاري فهود للتجارة ش . م . م | D25: FAHUD DESERT TRADING CO | E25: Fahud Desert Trading Co | J25: Trading | L25: Al Batinah North | T25: unknown | AC25: reported | AD25: 0.55 | AE25: 2026-09-21 | AF25: Public directory observation; CR, legal status, contact, tax and procurement fields not independently verified in this research pass.
A26: OMBI-0025 | B26: FAHUD ENERGY SOLUTIONS L.L.C | C26: فهود لحلول الطاقة ش.م.م | D26: FAHUD ENERGY SOLUTIONS L.L.C | E26: Fahud Energy Solutions | G26: LLC | J26: Utilities | L26: Dhofar | T26: unknown | AC26: reported | AD26: 0.55 | AE26: 2026-09-21 | AF26: Public directory observation; CR, legal status, contact, tax and procurement fields not independently verified in this research pass.
A27: OMBI-0026 | B27: FAHUD OIL FILD SERVICES & ENERGY L.L.C. | C27: فهود لخدمات حقول النفط والطاقة ش م م | D27: FAHUD OIL FILD SERVICES & ENERGY L.L.C. | E27: Fahud Oil Fild Services & Energy | G27: LLC | J27: Oil & Gas | L27: Dhofar | T27: unknown | AC27: reported | AD27: 0.55 | AE27: 2026-09-21 | AF27: Public directory observation; CR, legal status, contact, tax and procurement fields not independently verified in this research pass.
A28: OMBI-0027 | B28: FAIR TRADE LLC. | C28: شركـــة فيرتريــــد ش.م.م | D28: FAIR TRADE LLC. | E28: Fair Trade | G28: LLC | J28: Trading | L28: Muscat | T28: unknown | AC28: reported | AD28: 0.55 | AE28: 2026-09-21 | AF28: Public directory observation; CR, legal status, contact, tax and procurement fields not independently verified in this research pass.
A29: OMBI-0028 | B29: FALCON OILFIELD SERVICES L.L.C. | C29: الصقر لخدمات النفط ش . م . م | D29: FALCON OILFIELD SERVICES L.L.C. | E29: Falcon Oilfield Services | G29: LLC | J29: Oil & Gas | L29: Muscat | T29: unknown | AC29: reported | AD29: 0.55 | AE29: 2026-09-21 | AF29: Public directory observation; CR, legal status, contact, tax and procurement fields not independently verified in this research pass.
A30: OMBI-0029 | B30: FALCON PACK TRADING L.L.C | C30: فالكون باك للتجارة ش.م.م | D30: FALCON PACK TRADING L.L.C | E30: Falcon Pack Trading | G30: LLC | J30: Trading | L30: Muscat | T30: unknown | AC30: reported | AD30: 0.55 | AE30: 2026-09-21 | AF30: Public directory observation; CR, legal status, contact, tax and procurement fields not independently verified in this research pass.
A31: OMBI-0030 | B31: FALCON TRADING L.L.C. | C31: صقر الباز للتجارة ش . م . م | D31: FALCON TRADING L.L.C. | E31: Falcon Trading | G31: LLC | J31: Trading | L31: Muscat | T31: unknown | AC31: reported | AD31: 0.55 | AE31: 2026-09-21 | AF31: Public directory observation; CR, legal status, contact, tax and procurement fields not independently verified in this research pass.
A32: OMBI-0031 | B32: FAST LINE TECHNICAL SERVICES SPC | C32: الخط السريع للخدمات التقنية ش.ش.و | D32: FAST LINE TECHNICAL SERVICES SPC | E32: Fast Line Technical Services | G32: SPC | J32: Technology | L32: Muscat | T32: unknown | AC32: reported | AD32: 0.55 | AE32: 2026-09-21 | AF32: Public directory observation; CR, legal status, contact, tax and procurement fields not independently verified in this research pass.
A33: OMBI-0032 | B33: FEDERAL TRANSFORMERS AND SWITCHGEARS L.L.C | C33: الاتحادية للمحولات والمفاتيح الكهربائية ش م م | D33: FEDERAL TRANSFORMERS AND SWITCHGEARS L.L.C | E33: Federal Transformers And Switchgears | G33: LLC | J33: Manufacturing | L33: Muscat | T33: unknown | AC33: reported | AD33: 0.55 | AE33: 2026-09-21 | AF33: Public directory observation; CR, legal status, contact, tax and procurement fields not independently verified in this research pass.
A34: OMBI-0033 | B34: FIRST NATIONAL COMPANY FOR OPERATION AND MAINTENANCE SERVICES LLC | C34: الشركة الوطنية الاولى لخدمات التشغيل والصيانة ش م م | D34: FIRST NATIONAL COMPANY FOR OPERATION AND MAINTENANCE SERVICES LLC | E34: First National Company For Operation And Maintenance Services | G34: LLC | J34: Construction | L34: Muscat | T34: unknown | AC34: reported | AD34: 0.55 | AE34: 2026-09-21 | AF34: Public directory observation; CR, legal status, contact, tax and procurement fields not independently verified in this research pass.
A35: OMBI-0034 | B35: FUJAIRAH ENGINEERING COMPANY L.L.C | C35: شركة الفجيرة الهندسية ش.م.م | D35: FUJAIRAH ENGINEERING COMPANY L.L.C | E35: Fujairah Engineering Company | G35: LLC | J35: Construction | L35: Muscat | T35: unknown | AC35: reported | AD35: 0.55 | AE35: 2026-09-21 | AF35: Public directory observation; CR, legal status, contact, tax and procurement fields not independently verified in this research pass.
A36: OMBI-0035 | B36: FUTURE PIPE INDUSTRIES L.L.C. | C36: المستقبل لصناعة الانابيب ش.م.م | D36: FUTURE PIPE INDUSTRIES L.L.C. | E36: Future Pipe Industries | G36: LLC | J36: Manufacturing | L36: Muscat | T36: unknown | AC36: reported | AD36: 0.55 | AE36: 2026-09-21 | AF36: Public directory observation; CR, legal status, contact, tax and procurement fields not independently verified in this research pass.
A37: OMBI-0036 | B37: GALFAR ASPIRE READY MIX SPC | C37: جلفار الطموح للخرسانه الجاهزة ش.ش.و | D37: GALFAR ASPIRE READY MIX SPC | E37: Galfar Aspire Ready Mix | G37: SPC | J37: Construction | L37: Muscat | T37: unknown | AC37: reported | AD37: 0.55 | AE37: 2026-09-21 | AF37: Public directory observation; CR, legal status, contact, tax and procurement fields not independently verified in this research pass.
A38: OMBI-0037 | B38: GALFAR ENGINEERING AND CONTRACTING | C38: جلفار للهندسة والمقاولات | D38: GALFAR ENGINEERING AND CONTRACTING | E38: Galfar Engineering And Contracting | J38: Construction | L38: Muscat | T38: unknown | AC38: reported | AD38: 0.55 | AE38: 2026-09-21 | AF38: Public directory observation; CR, legal status, contact, tax and procurement fields not independently verified in this research pass.
A39: OMBI-0038 | B39: GLOBAL CHEMICAL & MAINTENANCE SYSTEMS LLC | C39: شركة جلوبال للانظمة الكيميائية والصيانة المحدودة ش.م.م | D39: GLOBAL CHEMICAL & MAINTENANCE SYSTEMS LLC | E39: Global Chemical & Maintenance Systems | G39: LLC | J39: Manufacturing | L39: Muscat | T39: unknown | AC39: reported | AD39: 0.55 | AE39: 2026-09-21 | AF39: Public directory observation; CR, legal status, contact, tax and procurement fields not independently verified in this research pass.
A40: OMBI-0039 | B40: GLOBAL COMPUTER SERVICES CORPORTION | C40: الشركة الدولية لخدمات الحاسب الالي ش . م . م | D40: GLOBAL COMPUTER SERVICES CORPORTION | E40: Global Computer Services Corportion | J40: Other | L40: Muscat | T40: unknown | AC40: reported | AD40: 0.55 | AE40: 2026-09-21 | AF40: Public directory observation; CR, legal status, contact, tax and procurement fields not independently verified in this research pass.
...

Sheet Sources
A1: company_id | B1: company_name | C1: field_or_category | D1: source_name | E1: source_type | F1: source_url | G1: source_record_id | H1: observed_at | I1: verification_status | J1: source_authority | K1: notes
A2: OMBI-0001 | B2: DHOFAR POULTRY CO. (S.A.O.G.) | C2: identity; Arabic name; industry; governorate | D2: Cardify Oman Business Index | E2: public_directory | F2: https://cardify.om/companies?page=8 | G2: page-8 | H2: 2026-09-21 | I2: reported | J2: 0.5 | K2: Directory states data is derived from MoCIIP public register; sector/governorate may be directory-classified.
A3: OMBI-0002 | B3: DHOFAR UNIVERSITY | C3: identity; Arabic name; industry; governorate | D3: Cardify Oman Business Index | E3: public_directory | F3: https://cardify.om/companies?page=8 | G3: page-8 | H3: 2026-09-21 | I3: reported | J3: 0.5 | K3: Directory states data is derived from MoCIIP public register; sector/governorate may be directory-classified.
A4: OMBI-0003 | B4: DIAMOND GULF INTERNATIONAL L L C | C4: identity; Arabic name; industry; governorate | D4: Cardify Oman Business Index | E4: public_directory | F4: https://cardify.om/companies?page=8 | G4: page-8 | H4: 2026-09-21 | I4: reported | J4: 0.5 | K4: Directory states data is derived from MoCIIP public register; sector/governorate may be directory-classified.
A5: OMBI-0004 | B5: DIRECT SERVICES LLC | C5: identity; Arabic name; industry; governorate | D5: Cardify Oman Business Index | E5: public_directory | F5: https://cardify.om/companies?page=8 | G5: page-8 | H5: 2026-09-21 | I5: reported | J5: 0.5 | K5: Directory states data is derived from MoCIIP public register; sector/governorate may be directory-classified.
A6: OMBI-0005 | B6: DOHAT AL KHALEEJ L.L.C. | C6: identity; Arabic name; industry; governorate | D6: Cardify Oman Business Index | E6: public_directory | F6: https://cardify.om/companies?page=8 | G6: page-8 | H6: 2026-09-21 | I6: reported | J6: 0.5 | K6: Directory states data is derived from MoCIIP public register; sector/governorate may be directory-classified.
A7: OMBI-0006 | B7: DOHT AL SHMOOKH TRAD | C7: identity; Arabic name; industry; governorate | D7: Cardify Oman Business Index | E7: public_directory | F7: https://cardify.om/companies?page=8 | G7: page-8 | H7: 2026-09-21 | I7: reported | J7: 0.5 | K7: Directory states data is derived from MoCIIP public register; sector/governorate may be directory-classified.
A8: OMBI-0007 | B8: DOKA MUSCAT SPC | C8: identity; Arabic name; industry; governorate | D8: Cardify Oman Business Index | E8: public_directory | F8: https://cardify.om/companies?page=8 | G8: page-8 | H8: 2026-09-21 | I8: reported | J8: 0.5 | K8: Directory states data is derived from MoCIIP public register; sector/governorate may be directory-classified.
A9: OMBI-0008 | B9: DOMINON VENTURES L L C | C9: identity; Arabic name; industry; governorate | D9: Cardify Oman Business Index | E9: public_directory | F9: https://cardify.om/companies?page=8 | G9: page-8 | H9: 2026-09-21 | I9: reported | J9: 0.5 | K9: Directory states data is derived from MoCIIP public register; sector/governorate may be directory-classified.
A10: OMBI-0009 | B10: DOUGLAS OHI LLC. | C10: identity; Arabic name; industry; governorate | D10: Cardify Oman Business Index | E10: public_directory | F10: https://cardify.om/companies?page=8 | G10: page-8 | H10: 2026-09-21 | I10: reported | J10: 0.5 | K10: Directory states data is derived from MoCIIP public register; sector/governorate may be directory-classified.
A11: OMBI-0010 | B11: DRAIEH CATERING & SERVICES CO. LLC | C11: identity; Arabic name; industry; governorate | D11: Cardify Oman Business Index | E11: public_directory | F11: https://cardify.om/companies?page=8 | G11: page-8 | H11: 2026-09-21 | I11: reported | J11: 0.5 | K11: Directory states data is derived from MoCIIP public register; sector/governorate may be directory-classified.
A12: OMBI-0011 | B12: DSV AIR AND SEA L L C | C12: identity; Arabic name; industry; governorate | D12: Cardify Oman Business Index | E12: public_directory | F12: https://cardify.om/companies?page=8 | G12: page-8 | H12: 2026-09-21 | I12: reported | J12: 0.5 | K12: Directory states data is derived from MoCIIP public register; sector/governorate may be directory-classified.
A13: OMBI-0012 | B13: DUCAB MUSCAT L.L.C | C13: identity; Arabic name; industry; governorate | D13: Cardify Oman Business Index | E13: public_directory | F13: https://cardify.om/companies?page=8 | G13: page-8 | H13: 2026-09-21 | I13: reported | J13: 0.5 | K13: Directory states data is derived from MoCIIP public register; sector/governorate may be directory-classified.
... A208: OMBI-0207 | B208: READYMIX MUSCAT LLC | C208: identity; Arabic name; industry; governorate | D208: Cardify Oman Business Index | E208: public_directory | F208: https://cardify.om/companies?page=15 | G208: page-15 | H208: 2026-09-21 | I208: reported | J208: 0.5 | K208: Directory states data is derived from MoCIIP public register; sector/governorate may be directory-classified.

Sheet Procurement
A1: company_id | B1: company_name | C1: registered_supplier | D1: supplier_category | E1: supplier_classification | F1: tenders_participated | G1: known_government_buyers | H1: last_tender_activity | I1: source_name | J1: source_url | K1: observed_at

Sheet Awards
A1: company_id | B1: company_name | C1: tender_number | D1: buyer | E1: title | F1: category | G1: award_value_omr | H1: award_date | I1: source_name | J1: source_url | K1: observed_at

Sheet Tax Verification
A1: company_id | B1: company_name | C1: cr_number | D1: vat_number | E1: tax_verification_status | F1: verified_at | G1: source_name | H1: source_url | I1: notes
A2: OMBI-0001 | B2: DHOFAR POULTRY CO. (S.A.O.G.) | E2: could_not_verify | I2: Tax verification not completed because no company-specific CR/VAT identifier was publicly verified in this pass.
A3: OMBI-0002 | B3: DHOFAR UNIVERSITY | E3: could_not_verify | I3: Tax verification not completed because no company-specific CR/VAT identifier was publicly verified in this pass.
A4: OMBI-0003 | B4: DIAMOND GULF INTERNATIONAL L L C | E4: could_not_verify | I4: Tax verification not completed because no company-specific CR/VAT identifier was publicly verified in this pass.
A5: OMBI-0004 | B5: DIRECT SERVICES LLC | E5: could_not_verify | I5: Tax verification not completed because no company-specific CR/VAT identifier was publicly verified in this pass.
A6: OMBI-0005 | B6: DOHAT AL KHALEEJ L.L.C. | E6: could_not_verify | I6: Tax verification not completed because no company-specific CR/VAT identifier was publicly verified in this pass.
A7: OMBI-0006 | B7: DOHT AL SHMOOKH TRAD | E7: could_not_verify | I7: Tax verification not completed because no company-specific CR/VAT identifier was publicly verified in this pass.
A8: OMBI-0007 | B8: DOKA MUSCAT SPC | E8: could_not_verify | I8: Tax verification not completed because no company-specific CR/VAT identifier was publicly verified in this pass.
A9: OMBI-0008 | B9: DOMINON VENTURES L L C | E9: could_not_verify | I9: Tax verification not completed because no company-specific CR/VAT identifier was publicly verified in this pass.
A10: OMBI-0009 | B10: DOUGLAS OHI LLC. | E10: could_not_verify | I10: Tax verification not completed because no company-specific CR/VAT identifier was publicly verified in this pass.
A11: OMBI-0010 | B11: DRAIEH CATERING & SERVICES CO. LLC | E11: could_not_verify | I11: Tax verification not completed because no company-specific CR/VAT identifier was publicly verified in this pass.
A12: OMBI-0011 | B12: DSV AIR AND SEA L L C | E12: could_not_verify | I12: Tax verification not completed because no company-specific CR/VAT identifier was publicly verified in this pass.
A13: OMBI-0012 | B13: DUCAB MUSCAT L.L.C | E13: could_not_verify | I13: Tax verification not completed because no company-specific CR/VAT identifier was publicly verified in this pass.
... A208: OMBI-0207 | B208: READYMIX MUSCAT LLC | E208: could_not_verify | I208: Tax verification not completed because no company-specific CR/VAT identifier was publicly verified in this pass.

Sheet Review Queue
A1: company_id | B1: company_name | C1: issue_type | D1: issue_description | E1: source_1 | F1: source_2 | G1: recommended_action
A2: OMBI-0001 | B2: DHOFAR POULTRY CO. (S.A.O.G.) | C2: missing CR | D2: CR number was not verified from an accessible authoritative source. | E2: https://cardify.om/companies?page=8 | G2: Verify CR via MoCIIP/Oman Business public lookup or official company documents; do not infer from name.
A3: OMBI-0002 | B3: DHOFAR UNIVERSITY | C3: missing CR | D3: CR number was not verified from an accessible authoritative source. | E3: https://cardify.om/companies?page=8 | G3: Verify CR via MoCIIP/Oman Business public lookup or official company documents; do not infer from name.
A4: OMBI-0003 | B4: DIAMOND GULF INTERNATIONAL L L C | C4: missing CR | D4: CR number was not verified from an accessible authoritative source. | E4: https://cardify.om/companies?page=8 | G4: Verify CR via MoCIIP/Oman Business public lookup or official company documents; do not infer from name.
A5: OMBI-0004 | B5: DIRECT SERVICES LLC | C5: missing CR | D5: CR number was not verified from an accessible authoritative source. | E5: https://cardify.om/companies?page=8 | G5: Verify CR via MoCIIP/Oman Business public lookup or official company documents; do not infer from name.
A6: OMBI-0005 | B6: DOHAT AL KHALEEJ L.L.C. | C6: missing CR | D6: CR number was not verified from an accessible authoritative source. | E6: https://cardify.om/companies?page=8 | G6: Verify CR via MoCIIP/Oman Business public lookup or official company documents; do not infer from name.
A7: OMBI-0006 | B7: DOHT AL SHMOOKH TRAD | C7: missing CR | D7: CR number was not verified from an accessible authoritative source. | E7: https://cardify.om/companies?page=8 | G7: Verify CR via MoCIIP/Oman Business public lookup or official company documents; do not infer from name.
A8: OMBI-0007 | B8: DOKA MUSCAT SPC | C8: missing CR | D8: CR number was not verified from an accessible authoritative source. | E8: https://cardify.om/companies?page=8 | G8: Verify CR via MoCIIP/Oman Business public lookup or official company documents; do not infer from name.
A9: OMBI-0008 | B9: DOMINON VENTURES L L C | C9: missing CR | D9: CR number was not verified from an accessible authoritative source. | E9: https://cardify.om/companies?page=8 | G9: Verify CR via MoCIIP/Oman Business public lookup or official company documents; do not infer from name.
A10: OMBI-0009 | B10: DOUGLAS OHI LLC. | C10: missing CR | D10: CR number was not verified from an accessible authoritative source. | E10: https://cardify.om/companies?page=8 | G10: Verify CR via MoCIIP/Oman Business public lookup or official company documents; do not infer from name.
A11: OMBI-0010 | B11: DRAIEH CATERING & SERVICES CO. LLC | C11: missing CR | D11: CR number was not verified from an accessible authoritative source. | E11: https://cardify.om/companies?page=8 | G11: Verify CR via MoCIIP/Oman Business public lookup or official company documents; do not infer from name.
A12: OMBI-0011 | B12: DSV AIR AND SEA L L C | C12: missing CR | D12: CR number was not verified from an accessible authoritative source. | E12: https://cardify.om/companies?page=8 | G12: Verify CR via MoCIIP/Oman Business public lookup or official company documents; do not infer from name.
A13: OMBI-0012 | B13: DUCAB MUSCAT L.L.C | C13: missing CR | D13: CR number was not verified from an accessible authoritative source. | E13: https://cardify.om/companies?page=8 | G13: Verify CR via MoCIIP/Oman Business public lookup or official company documents; do not infer from name.
... A208: OMBI-0207 | B208: READYMIX MUSCAT LLC | C208: missing CR | D208: CR number was not verified from an accessible authoritative source. | E208: https://cardify.om/companies?page=15 | G208: Verify CR via MoCIIP/Oman Business public lookup or official company documents; do not infer from name.

Sheet Data Quality
A1: metric | B1: count | C1: percentage | D1: definition | F1: Research Notes
A2: total_companies | B2: =COUNTA(Companies!A2:A208) | C2: =B2/B2 | D2: Rows in Companies | F2: This is a verified-transcription research batch from publicly accessible Cardify pages. Missing authoritative identifiers are intentionally blank and queued for review.
A3: companies_with_cr | B3: =COUNTIF(Companies!F2:F208,"?*") | C3: =B3/$B$2 | D3: CR number present
A4: companies_with_status | B4: =COUNTIF(Companies!H2:H208,"?*") | C4: =B4/$B$2 | D4: Company status present
A5: companies_with_industry | B5: =COUNTIF(Companies!J2:J208,"?*") | C5: =B5/$B$2 | D5: Industry present
A6: companies_with_governorate | B6: =COUNTIF(Companies!L2:L208,"?*") | C6: =B6/$B$2 | D6: Governorate present
A7: companies_with_website | B7: =COUNTIF(Companies!P2:P208,"?*") | C7: =B7/$B$2 | D7: Website present
A8: companies_with_email | B8: =COUNTIF(Companies!Q2:Q208,"?*") | C8: =B8/$B$2 | D8: Business email present
A9: tax_verified | B9: =COUNTIF(Companies!T2:T208,"verified") | C9: =B9/$B$2 | D9: Tax status verified
A10: registered_suppliers | B10: =COUNTIF(Companies!U2:U208,TRUE) | C10: =B10/$B$2 | D10: Registered supplier TRUE
A11: companies_with_awards | B11: =COUNTIF(Companies!Y2:Y208,">0") | C11: =B11/$B$2 | D11: Award count >0
A12: companies_with_multiple_sources | B12: 0 | C12: =B12/$B$2 | D12: No multi-source identity confirmations completed
A13: low_confidence_companies | B13: =COUNTIF(Companies!AD2:AD208,"<0.60") | C13: =B13/$B$2 | D13: Confidence below 0.60
A14: needs_review | B14: =COUNTA('Review Queue'!A2:A208) | C14: =B14/$B$2 | D14: Rows in Review Queue
